<?xml version="1.0" encoding="utf-8"?>
<!-- HYUMM Scan Mobile Manipulator URDF
     Base joints (lin_x, lin_y, rot_z) removed - OCS2 adds virtual joints internally
-->
<robot name="hyumm_scan">
  <material name="black">
    <color rgba="0.0 0.0 0.0 1.0"/>
  </material>
  <material name="blue">
    <color rgba="0.0 0.0 0.8 1.0"/>
  </material>
  <material name="green">
    <color rgba="0.0 0.8 0.0 1.0"/>
  </material>
  <material name="grey_">
    <color rgba="0.2 0.2 0.2 1.0"/>
  </material>
  <material name="orange">
    <color rgba="1.0 0.4235294117647059 0.0392156862745098 1.0"/>
  </material>
  <material name="brown">
    <color rgba="0.8705882352941177 0.8117647058823529 0.7647058823529411 1.0"/>
  </material>
  <material name="red">
    <color rgba="0.8 0.0 0.0 1.0"/>
  </material>
  <material name="white">
    <color rgba="1.0 1.0 1.0 1.0"/>
  </material>
  <material name="metal">
    <color rgba="0.768627450980392 0.749019607843137 0.729411764705882 1"/>
  </material>
  <material name="metal_grey">
    <color rgba="0.501960784313725 0.501960784313725 0.501960784313725 1"/>
  </material>
  <material name="metal_white">
    <color rgba="0.866666666666667 0.866666666666667 0.890196078431373 1"/>
  </material>

  <!-- Mobile Base -->
  <link name="base_link">
    <inertial>
      <origin xyz="-0.02314163 0 0.14646583" rpy="0 0 0" />
      <mass value="53.53736408" />
      <inertia
        ixx="1.81165434"
        ixy="0.01131605"
        ixz="0.08235226"
        iyy="4.92583072"
        iyz="0.00000413"
        izz="6.44882489" />
    </inertial>
    <visual>
      <origin xyz="0 0 0" rpy="0 0 0" />
      <geometry>
        <mesh filename="package://hyumm_description/meshes/base/base_link.STL" />
      </geometry>
      <material name="">
        <color rgba="0.79216 0.81961 0.93333 1" />
      </material>
    </visual>
    <collision>
      <origin xyz="-0.5 -0.325 0" rpy="0 0 0" />
      <geometry>
        <mesh filename="package://hyumm_description/meshes/base/base_collision.STL"/>
      </geometry>
    </collision>
  </link>

  <!-- Manipulator Indy7 -->
  <link name="link0">
    <visual>
      <origin rpy="0 0 0" xyz="0 0 0"/>
      <geometry>
        <mesh filename="package://hyumm_description/meshes/indy7/visual/Indy7_0.stl"/>
      </geometry>
      <material name="metal_grey"/>
    </visual>
    <collision>
      <origin rpy="0 0 0" xyz="0 0 0"/>
      <geometry>
        <mesh filename="package://hyumm_description/meshes/indy7/collision/Indy7_0.stl"/>
      </geometry>
    </collision>
    <inertial>
      <origin xyz="0.00131966 -0.00000218 0.03212832" rpy="0 0 0"/>
      <mass value="1.67030785"/>
      <inertia ixx="+0.00661309" iyy="+0.00644765" izz="+0.00792090" ixy="+0.00000183" iyz="-0.00000027" ixz="+0.00002695"/>
    </inertial>
  </link>
  <link name="link1">
    <visual>
      <origin rpy="0 0 0" xyz="0 0 0"/>
      <geometry>
        <mesh filename="package://hyumm_description/meshes/indy7/visual/Indy7_1.stl"/>
      </geometry>
      <material name="metal_grey"/>
    </visual>
    <collision>
      <origin rpy="0 0 0" xyz="0 0 0"/>
      <geometry>
        <mesh filename="package://hyumm_description/meshes/indy7/collision/Indy7_1.stl"/>
      </geometry>
    </collision>
    <inertial>
      <origin xyz="-0.00023749 -0.04310313 0.13245396" rpy="0 0 0"/>
      <mass value="11.44444535"/>
      <inertia ixx="+0.35065005" iyy="+0.30479800" izz="+0.06003147" ixy="+0.00011931" iyz="-0.10984447" ixz="-0.00037553"/>
    </inertial>
  </link>
  <link name="link2">
    <visual>
      <origin rpy="0 0 0" xyz="0 0 0"/>
      <geometry>
        <mesh filename="package://hyumm_description/meshes/indy7/visual/Indy7_2.stl"/>
      </geometry>
      <material name="metal_grey"/>
    </visual>
    <collision>
      <origin rpy="0 0 0" xyz="0 0 0"/>
      <geometry>
        <mesh filename="package://hyumm_description/meshes/indy7/collision/Indy7_2.stl"/>
      </geometry>
    </collision>
    <inertial>
      <origin xyz="-0.29616699 0.00002254 0.04483069" rpy="0 0 0"/>
      <mass value="5.84766553"/>
      <inertia ixx="+0.03599743" iyy="+0.72293306" izz="+0.70024119" ixy="-0.00004693" iyz="+0.00000176" ixz="-0.05240346"/>
    </inertial>
  </link>
  <link name="link3">
    <visual>
      <origin rpy="0 0 0" xyz="0 0 0"/>
      <geometry>
        <mesh filename="package://hyumm_description/meshes/indy7/visual/Indy7_3.stl"/>
      </geometry>
      <material name="metal_grey"/>
    </visual>
    <collision>
      <origin rpy="0 0 0" xyz="0 0 0"/>
      <geometry>
        <mesh filename="package://hyumm_description/meshes/indy7/collision/Indy7_3.stl"/>
      </geometry>
    </collision>
    <inertial>
      <origin xyz="-0.16804016 0.00021421 -0.07000383" rpy="0 0 0"/>
      <mass value="2.68206064"/>
      <inertia ixx="+0.01617210" iyy="+0.11364055" izz="+0.10022522" ixy="-0.00011817" iyz="-0.00004371" ixz="+0.03341882"/>
    </inertial>
  </link>
  <link name="link4">
    <visual>
      <origin rpy="0 0 0" xyz="0 0 0"/>
      <geometry>
        <mesh filename="package://hyumm_description/meshes/indy7/visual/Indy7_4.stl"/>
      </geometry>
      <material name="metal_grey"/>
    </visual>
    <collision>
      <origin rpy="0 0 0" xyz="0 0 0"/>
      <geometry>
        <mesh filename="package://hyumm_description/meshes/indy7/collision/Indy7_4.stl"/>
      </geometry>
    </collision>
    <inertial>
      <origin xyz="-0.00026847 -0.07098440 0.07649128" rpy="0 0 0"/>
      <mass value="2.12987371"/>
      <inertia ixx="+0.02798891" iyy="+0.01443076" izz="+0.01496211" ixy="+0.00003893" iyz="-0.01266296" ixz="-0.00004768"/>
    </inertial>
  </link>
  <link name="link5">
    <visual>
      <origin rpy="0 0 0" xyz="0 0 0"/>
      <geometry>
        <mesh filename="package://hyumm_description/meshes/indy7/visual/Indy7_5.stl"/>
      </geometry>
      <material name="metal_grey"/>
    </visual>
    <collision>
      <origin rpy="0 0 0" xyz="0 0 0"/>
      <geometry>
        <mesh filename="package://hyumm_description/meshes/indy7/collision/Indy7_5.stl"/>
      </geometry>
    </collision>
    <inertial>
      <origin xyz="-0.09796232 -0.00023114 0.06445892" rpy="0 0 0"/>
      <mass value="2.22412271"/>
      <inertia ixx="+0.01105297" iyy="+0.03698291" izz="+0.02754795" ixy="+0.00005517" iyz="-0.00003740" ixz="-0.01481977"/>
    </inertial>
  </link>
  <link name="link6">
    <visual>
      <origin rpy="0 0 0" xyz="0 0 0"/>
      <geometry>
        <mesh filename="package://hyumm_description/meshes/indy7/visual/Indy7_6.stl"/>
      </geometry>
      <material name="metal_grey"/>
    </visual>
    <collision>
      <origin rpy="0 0 0" xyz="0 0 0"/>
      <geometry>
        <mesh filename="package://hyumm_description/meshes/indy7/collision/Indy7_6.stl"/>
      </geometry>
    </collision>
    <inertial>
      <origin xyz="0.00008147 -0.00046556 0.03079097" rpy="0 0 0"/>
      <mass value="0.38254932"/>
      <inertia ixx="+0.00078982" iyy="+0.00079764" izz="+0.00058319" ixy="-0.00000034" iyz="-0.00000508" ixz="+0.00000083"/>
    </inertial>
  </link>
  <link name="link_scanner">
    <visual>
      <origin rpy="0 0 0" xyz="0 0 0"/>
      <geometry>
        <mesh filename="package://hyumm_description/meshes/indy7/visual/scanner.stl"/>
      </geometry>
      <material name="metal_grey"/>
    </visual>
    <collision>
      <origin rpy="0 0 0" xyz="0 0 0"/>
      <geometry>
        <mesh filename="package://hyumm_description/meshes/indy7/collision/scanner.stl"/>
      </geometry>
    </collision>
    <inertial>
      <origin xyz="0.03402729 0.00001589 0.11025973" rpy="0 0 0"/>
      <mass value="1.305"/>
      <inertia ixx="0.00403396" iyy="-0.00000111" izz="0.00032561" ixy="0.00874370" iyz="-0.00000018" ixz="0.00742055"/>
    </inertial>
  </link>
  <link name="tcp">
    <inertial>
      <mass value="0" />
      <origin xyz="0.0 0.0 0.0" rpy="0 0 0" />
      <inertia ixx="0" ixy="0" ixz="0" iyy="0" iyz="0" izz="0" />
    </inertial>
  </link>

  <!-- Joints -->
  <joint name="base_flange" type="fixed">
    <parent link="base_link"/>
    <child link="link0"/>
    <origin xyz="0.3 0 0.228" rpy="0 0 0"/>
  </joint>
  <joint name="joint0" type="revolute">
    <parent link="link0"/>
    <child link="link1"/>
    <origin rpy="0 0 0" xyz="0 0 0.0775"/>
    <axis xyz="0 0 1"/>
    <limit effort="10" lower="-3.0543261909900763" upper="3.0543261909900763" velocity="1"/>
  </joint>
  <joint name="joint1" type="revolute">
    <parent link="link1"/>
    <child link="link2"/>
    <origin rpy="1.5707963267948966 1.5707963267948966 0" xyz="0 -0.10900000 0.22200000"/>
    <axis xyz="0 0 1"/>
    <limit effort="10" lower="-3.0543261909900763" upper="3.0543261909900763" velocity="1"/>
  </joint>
  <joint name="joint2" type="revolute">
    <parent link="link2"/>
    <child link="link3"/>
    <origin rpy="0 0 0" xyz="-0.45000000 +0.00000000 -0.03050000"/>
    <axis xyz="0 0 1"/>
    <limit effort="10" lower="-3.0543261909900763" upper="3.0543261909900763" velocity="1"/>
  </joint>
  <joint name="joint3" type="revolute">
    <parent link="link3"/>
    <child link="link4"/>
    <origin rpy="-1.5707963267948966 0 1.5707963267948966" xyz="-0.26700000 +0.00000000 -0.07500000"/>
    <axis xyz="0 0 1"/>
    <limit effort="10" lower="-3.0543261909900763" upper="3.0543261909900763" velocity="1"/>
  </joint>
  <joint name="joint4" type="revolute">
    <parent link="link4"/>
    <child link="link5"/>
    <origin rpy="1.5707963267948966 1.5707963267948966 0" xyz="+0.00000000 -0.11400000 +0.08300000"/>
    <axis xyz="0 0 1"/>
    <limit effort="10" lower="-3.0543261909900763" upper="3.0543261909900763" velocity="1"/>
  </joint>
  <joint name="joint5" type="revolute">
    <parent link="link5"/>
    <child link="link6"/>
    <origin rpy="-1.5707963267948966 0 1.5707963267948966" xyz="-0.16800000 +0.00000000 +0.06900000"/>
    <axis xyz="0 0 1"/>
    <limit effort="10" lower="-3.752457891787808" upper="3.752457891787808" velocity="1"/>
  </joint>
  <joint name="fixed_scanner" type="fixed">
    <parent link="link6"/>
    <child link="link_scanner"/>
    <origin rpy="0 0 0" xyz="0 0 0.0615"/>
  </joint>
  <joint name="indy7_tcp" type="fixed">
    <parent link="link_scanner"/>
    <child link="tcp"/>
    <origin rpy="3.2531185 0.0 -1.57079" xyz="0.06906692 0.00036944 0.19936873"/>
  </joint>

</robot>
